<?xml version="1.0" encoding="utf-8"?>
<!-- This URDF was automatically created by SolidWorks to URDF Exporter! Originally created by Stephen Brawner (brawner@gmail.com) 
     Commit Version: 1.6.0-4-g7f85cfe  Build Version: 1.6.7995.38578
     For more information, please see http://wiki.ros.org/sw_urdf_exporter -->
<robot
  name="robot_description">
  
  <!-- Base footprint link - ground reference -->
  <link name="base_footprint">
    <inertial>
      <mass value="0.0001" />
      <origin xyz="0 0 0" />
      <inertia ixx="0.0001" ixy="0.0" ixz="0.0" iyy="0.0001" iyz="0.0" izz="0.0001" />
    </inertial>
  </link>
  
  <!-- Joint connecting base_footprint to base_link -->
  <joint name="base_footprint_joint" type="fixed">
    <origin xyz="0 0 0.05" rpy="0 0 0"/>
    <parent link="base_footprint"/>
    <child link="base_link"/>
  </joint>
  
  <link
    name="base_link">
    <inertial>
      <origin
        xyz="2.6246E-14 2.3582E-14 -0.0015"
        rpy="0 0 0" />
      <mass
        value="0.039002" />
      <inertia
        ixx="3.2716E-05"
        ixy="-2.1462E-13"
        ixz="-2.6892E-20"
        iyy="6.7767E-05"
        iyz="1.2263E-20"
        izz="0.00010042" />
    </inertial>
    <visual>
      <origin
        xyz="0 0 0"
        rpy="0 0 0" />
      <geometry>
        <mesh
          filename="package://robot_description/meshes/base_link.STL" />
      </geometry>
      <material
        name="">
        <color
          rgba="0.79216 0.81961 0.93333 1" />
      </material>
    </visual>
    <collision>
      <origin
        xyz="0 0 0"
        rpy="0 0 0" />
      <geometry>
        <mesh
          filename="package://robot_description/meshes/base_link.STL" />
      </geometry>
    </collision>
  </link>
  <link
    name="wheel_left_Link">
    <inertial>
      <origin
        xyz="3.2081E-06 -0.027055 0.00013509"
        rpy="0 0 0" />
      <mass
        value="0.035371" />
      <inertia
        ixx="7.2964E-06"
        ixy="-1.2651E-09"
        ixz="-6.992E-11"
        iyy="7.5055E-06"
        iyz="1.0517E-07"
        izz="7.2459E-06" />
    </inertial>
    <visual>
      <origin
        xyz="0 0 0"
        rpy="0 0 0" />
      <geometry>
        <mesh
          filename="package://robot_description/meshes/wheel_left_Link.STL" />
      </geometry>
      <material
        name="">
        <color
          rgba="0.79216 0.81961 0.93333 1" />
      </material>
    </visual>
    <collision>
      <origin
        xyz="0 0 0"
        rpy="0 0 0" />
      <geometry>
        <mesh
          filename="package://robot_description/meshes/wheel_left_Link.STL" />
      </geometry>
    </collision>
  </link>
  <joint
    name="wheel_left_joint"
    type="continuous">
    <origin
      xyz="-0.048791 0.0715 -0.023"
      rpy="0 0 0" />
    <parent
      link="base_link" />
    <child
      link="wheel_left_Link" />
    <axis
      xyz="0 -1 0" />
  </joint>

  <!-- Gazebo properties for left wheel -->
  <gazebo reference="wheel_left_Link">
    <material>Gazebo/Black</material>
    <mu1>1.0</mu1>
    <mu2>1.0</mu2>
    <kp>1000000.0</kp>
    <kd>1.0</kd>
    <minDepth>0.001</minDepth>
    <maxVel>1.0</maxVel>
  </gazebo>
  <link
    name="wheel_right_Link">
    <inertial>
      <origin
        xyz="-3.2081E-06 0.027055 0.00013509"
        rpy="0 0 0" />
      <mass
        value="0.035371" />
      <inertia
        ixx="7.2964E-06"
        ixy="-1.2651E-09"
        ixz="6.992E-11"
        iyy="7.5055E-06"
        iyz="-1.0517E-07"
        izz="7.2459E-06" />
    </inertial>
    <visual>
      <origin
        xyz="0 0 0"
        rpy="0 0 0" />
      <geometry>
        <mesh
          filename="package://robot_description/meshes/wheel_right_Link.STL" />
      </geometry>
      <material
        name="">
        <color
          rgba="0.79216 0.81961 0.93333 1" />
      </material>
    </visual>
    <collision>
      <origin
        xyz="0 0 0"
        rpy="0 0 0" />
      <geometry>
        <mesh
          filename="package://robot_description/meshes/wheel_right_Link.STL" />
      </geometry>
    </collision>
  </link>
  <joint
    name="wheel_right_joint"
    type="continuous">
    <origin
      xyz="-0.048791 -0.0715 -0.023"
      rpy="0 0 0" />
    <parent
      link="base_link" />
    <child
      link="wheel_right_Link" />
    <axis
      xyz="0 -1 0" />
  </joint>

  <!-- Gazebo properties for right wheel -->
  <gazebo reference="wheel_right_Link">
    <material>Gazebo/Black</material>
    <mu1>1.0</mu1>
    <mu2>1.0</mu2>
    <kp>1000000.0</kp>
    <kd>1.0</kd>
    <minDepth>0.001</minDepth>
    <maxVel>1.0</maxVel>
  </gazebo>
  <link
    name="wheel_universal_Link">
    <inertial>
      <origin
        xyz="-0.0049043 0.0072459 0.0084569"
        rpy="0 0 0" />
      <mass
        value="0.010932" />
      <inertia
        ixx="1.9746E-06"
        ixy="1.5756E-10"
        ixz="7.6294E-07"
        iyy="2.4635E-06"
        iyz="-2.4689E-10"
        izz="1.3438E-06" />
    </inertial>
    <visual>
      <origin
        xyz="0 0 0"
        rpy="0 0 0" />
      <geometry>
        <mesh
          filename="package://robot_description/meshes/wheel_universal_Link.STL" />
      </geometry>
      <material
        name="">
        <color
          rgba="0.74118 0.90196 0.95686 1" />
      </material>
    </visual>
    <collision>
      <origin
        xyz="0 0 0"
        rpy="0 0 0" />
      <geometry>
        <mesh
          filename="package://robot_description/meshes/wheel_universal_Link.STL" />
      </geometry>
    </collision>
  </link>
  <joint
    name="wheel_universal_joint"
    type="fixed">
    <origin
      xyz="0.063633 -0.0072487 -0.034"
      rpy="0 0 0" />
    <parent
      link="base_link" />
    <child
      link="wheel_universal_Link" />
    <axis
      xyz="0 0 0" />
  </joint>
  <link
    name="laser_Link">
    <inertial>
      <origin
        xyz="-0.0030189 -0.00020139 -0.019649"
        rpy="0 0 0" />
      <mass
        value="0.094023" />
      <inertia
        ixx="3.4259E-05"
        ixy="-1.2348E-09"
        ixz="-2.1308E-07"
        iyy="5.7727E-05"
        iyz="-8.9097E-10"
        izz="7.5176E-05" />
    </inertial>
    <visual>
      <origin
        xyz="0 0 0"
        rpy="0 0 0" />
      <geometry>
        <mesh
          filename="package://robot_description/meshes/laser_Link.STL" />
      </geometry>
      <material
        name="">
        <color
          rgba="0.37255 0.55686 1 1" />
      </material>
    </visual>
    <collision>
      <origin
        xyz="0 0 0"
        rpy="0 0 0" />
      <geometry>
        <mesh
          filename="package://robot_description/meshes/laser_Link.STL" />
      </geometry>
    </collision>
  </link>
  <joint
    name="laser_joint"
    type="fixed">
    <origin
      xyz="-0.0064435 0.002216 0.078664"
      rpy="0 0 3.1416" />
    <parent
      link="base_link" />
    <child
      link="laser_Link" />
    <axis
      xyz="0 0 0" />
  </joint>
  <link
    name="imu_Link">
    <inertial>
      <origin
        xyz="-0.021463 0.017572 -0.010408"
        rpy="0 0 0" />
      <mass
        value="0.017226" />
      <inertia
        ixx="2.2162E-06"
        ixy="3.6168E-10"
        ixz="-1.8429E-08"
        iyy="4.9944E-06"
        iyz="3.6637E-11"
        izz="7.034E-06" />
    </inertial>
    <visual>
      <origin
        xyz="0 0 0"
        rpy="0 0 0" />
      <geometry>
        <mesh
          filename="package://robot_description/meshes/imu_Link.STL" />
      </geometry>
      <material
        name="">
        <color
          rgba="1 1 1 1" />
      </material>
    </visual>
    <collision>
      <origin
        xyz="0 0 0"
        rpy="0 0 0" />
      <geometry>
        <mesh
          filename="package://robot_description/meshes/imu_Link.STL" />
      </geometry>
    </collision>
  </link>
  <joint
    name="imu_joint"
    type="fixed">
    <origin
      xyz="0.037033 -0.018447 0.013909"
      rpy="0 0 0" />
    <parent
      link="base_link" />
    <child
      link="imu_Link" />
    <axis
      xyz="0 0 0" />
  </joint>

  <!-- Gazebo ros_control plugin -->
  <gazebo>
    <plugin name="gazebo_ros_control" filename="libgazebo_ros_control.so">
      <robotNamespace>/</robotNamespace>
    </plugin>
  </gazebo>

  <!-- Differential drive controller -->
  <gazebo>
    <plugin name="differential_drive_controller" filename="libgazebo_ros_diff_drive.so">
      <alwaysOn>true</alwaysOn>
      <updateRate>50</updateRate>
      <leftJoint>wheel_left_joint</leftJoint>
      <rightJoint>wheel_right_joint</rightJoint>
      <wheelSeparation>0.143</wheelSeparation>
      <wheelDiameter>0.054</wheelDiameter>
      <torque>20</torque>
      <commandTopic>cmd_vel</commandTopic>
      <odometryTopic>odom</odometryTopic>
      <odometryFrame>odom</odometryFrame>
      <robotBaseFrame>base_footprint</robotBaseFrame>
      <publishWheelTF>false</publishWheelTF>
      <publishWheelJointState>false</publishWheelJointState>
      <rosDebugLevel>na</rosDebugLevel>
    </plugin>
  </gazebo>

  <!-- Wheel transmissions for gazebo_ros_control -->
  <transmission name="wheel_left_joint_trans">
    <type>transmission_interface/SimpleTransmission</type>
    <joint name="wheel_left_joint">
      <hardwareInterface>hardware_interface/VelocityJointInterface</hardwareInterface>
    </joint>
    <actuator name="wheel_left_joint_motor">
      <hardwareInterface>hardware_interface/VelocityJointInterface</hardwareInterface>
      <mechanicalReduction>1</mechanicalReduction>
    </actuator>
  </transmission>

  <transmission name="wheel_right_joint_trans">
    <type>transmission_interface/SimpleTransmission</type>
    <joint name="wheel_right_joint">
      <hardwareInterface>hardware_interface/VelocityJointInterface</hardwareInterface>
    </joint>
    <actuator name="wheel_right_joint_motor">
      <hardwareInterface>hardware_interface/VelocityJointInterface</hardwareInterface>
      <mechanicalReduction>1</mechanicalReduction>
    </actuator>
  </transmission>

</robot>